{
 "cells": [
  {
   "cell_type": "code",
   "execution_count": 1,
   "id": "9e9a23c0",
   "metadata": {},
   "outputs": [
    {
     "name": "stdout",
     "output_type": "stream",
     "text": [
      "Collecting pydatasetNote: you may need to restart the kernel to use updated packages.\n"
     ]
    },
    {
     "name": "stderr",
     "output_type": "stream",
     "text": [
      "ERROR: Exception:\n",
      "Traceback (most recent call last):\n",
      "  File \"C:\\Users\\Palash\\anaconda3\\lib\\site-packages\\pip\\_vendor\\urllib3\\response.py\", line 435, in _error_catcher\n",
      "    yield\n",
      "  File \"C:\\Users\\Palash\\anaconda3\\lib\\site-packages\\pip\\_vendor\\urllib3\\response.py\", line 516, in read\n",
      "    data = self._fp.read(amt) if not fp_closed else b\"\"\n",
      "  File \"C:\\Users\\Palash\\anaconda3\\lib\\site-packages\\pip\\_vendor\\cachecontrol\\filewrapper.py\", line 90, in read\n",
      "    data = self.__fp.read(amt)\n",
      "  File \"C:\\Users\\Palash\\anaconda3\\lib\\http\\client.py\", line 463, in read\n",
      "    n = self.readinto(b)\n",
      "  File \"C:\\Users\\Palash\\anaconda3\\lib\\http\\client.py\", line 507, in readinto\n",
      "    n = self.fp.readinto(b)\n",
      "  File \"C:\\Users\\Palash\\anaconda3\\lib\\socket.py\", line 704, in readinto\n",
      "    return self._sock.recv_into(b)\n",
      "  File \"C:\\Users\\Palash\\anaconda3\\lib\\ssl.py\", line 1242, in recv_into\n",
      "    return self.read(nbytes, buffer)\n",
      "  File \"C:\\Users\\Palash\\anaconda3\\lib\\ssl.py\", line 1100, in read\n",
      "    return self._sslobj.read(len, buffer)\n",
      "socket.timeout: The read operation timed out\n",
      "\n",
      "During handling of the above exception, another exception occurred:\n",
      "\n",
      "Traceback (most recent call last):\n",
      "  File \"C:\\Users\\Palash\\anaconda3\\lib\\site-packages\\pip\\_internal\\cli\\base_command.py\", line 167, in exc_logging_wrapper\n",
      "    status = run_func(*args)\n",
      "  File \"C:\\Users\\Palash\\anaconda3\\lib\\site-packages\\pip\\_internal\\cli\\req_command.py\", line 247, in wrapper\n",
      "    return func(self, options, args)\n",
      "  File \"C:\\Users\\Palash\\anaconda3\\lib\\site-packages\\pip\\_internal\\commands\\install.py\", line 369, in run\n",
      "    requirement_set = resolver.resolve(\n",
      "  File \"C:\\Users\\Palash\\anaconda3\\lib\\site-packages\\pip\\_internal\\resolution\\resolvelib\\resolver.py\", line 92, in resolve\n",
      "    result = self._result = resolver.resolve(\n",
      "  File \"C:\\Users\\Palash\\anaconda3\\lib\\site-packages\\pip\\_vendor\\resolvelib\\resolvers.py\", line 481, in resolve\n",
      "    state = resolution.resolve(requirements, max_rounds=max_rounds)\n",
      "  File \"C:\\Users\\Palash\\anaconda3\\lib\\site-packages\\pip\\_vendor\\resolvelib\\resolvers.py\", line 348, in resolve\n",
      "    self._add_to_criteria(self.state.criteria, r, parent=None)\n",
      "  File \"C:\\Users\\Palash\\anaconda3\\lib\\site-packages\\pip\\_vendor\\resolvelib\\resolvers.py\", line 172, in _add_to_criteria\n",
      "    if not criterion.candidates:\n",
      "  File \"C:\\Users\\Palash\\anaconda3\\lib\\site-packages\\pip\\_vendor\\resolvelib\\structs.py\", line 151, in __bool__\n",
      "    return bool(self._sequence)\n",
      "  File \"C:\\Users\\Palash\\anaconda3\\lib\\site-packages\\pip\\_internal\\resolution\\resolvelib\\found_candidates.py\", line 155, in __bool__\n",
      "    return any(self)\n",
      "  File \"C:\\Users\\Palash\\anaconda3\\lib\\site-packages\\pip\\_internal\\resolution\\resolvelib\\found_candidates.py\", line 143, in <genexpr>\n",
      "    return (c for c in iterator if id(c) not in self._incompatible_ids)\n",
      "  File \"C:\\Users\\Palash\\anaconda3\\lib\\site-packages\\pip\\_internal\\resolution\\resolvelib\\found_candidates.py\", line 47, in _iter_built\n",
      "    candidate = func()\n",
      "  File \"C:\\Users\\Palash\\anaconda3\\lib\\site-packages\\pip\\_internal\\resolution\\resolvelib\\factory.py\", line 206, in _make_candidate_from_link\n",
      "    self._link_candidate_cache[link] = LinkCandidate(\n",
      "  File \"C:\\Users\\Palash\\anaconda3\\lib\\site-packages\\pip\\_internal\\resolution\\resolvelib\\candidates.py\", line 297, in __init__\n",
      "    super().__init__(\n",
      "  File \"C:\\Users\\Palash\\anaconda3\\lib\\site-packages\\pip\\_internal\\resolution\\resolvelib\\candidates.py\", line 162, in __init__\n",
      "    self.dist = self._prepare()\n",
      "  File \"C:\\Users\\Palash\\anaconda3\\lib\\site-packages\\pip\\_internal\\resolution\\resolvelib\\candidates.py\", line 231, in _prepare\n",
      "    dist = self._prepare_distribution()\n",
      "  File \"C:\\Users\\Palash\\anaconda3\\lib\\site-packages\\pip\\_internal\\resolution\\resolvelib\\candidates.py\", line 308, in _prepare_distribution\n",
      "    return preparer.prepare_linked_requirement(self._ireq, parallel_builds=True)\n",
      "  File \"C:\\Users\\Palash\\anaconda3\\lib\\site-packages\\pip\\_internal\\operations\\prepare.py\", line 438, in prepare_linked_requirement\n",
      "    return self._prepare_linked_requirement(req, parallel_builds)\n",
      "  File \"C:\\Users\\Palash\\anaconda3\\lib\\site-packages\\pip\\_internal\\operations\\prepare.py\", line 483, in _prepare_linked_requirement\n",
      "    local_file = unpack_url(\n",
      "  File \"C:\\Users\\Palash\\anaconda3\\lib\\site-packages\\pip\\_internal\\operations\\prepare.py\", line 165, in unpack_url\n",
      "    file = get_http_url(\n",
      "  File \"C:\\Users\\Palash\\anaconda3\\lib\\site-packages\\pip\\_internal\\operations\\prepare.py\", line 106, in get_http_url\n",
      "    from_path, content_type = download(link, temp_dir.path)\n",
      "  File \"C:\\Users\\Palash\\anaconda3\\lib\\site-packages\\pip\\_internal\\network\\download.py\", line 147, in __call__\n",
      "    for chunk in chunks:\n",
      "  File \"C:\\Users\\Palash\\anaconda3\\lib\\site-packages\\pip\\_internal\\cli\\progress_bars.py\", line 53, in _rich_progress_bar\n",
      "    for chunk in iterable:\n",
      "  File \"C:\\Users\\Palash\\anaconda3\\lib\\site-packages\\pip\\_internal\\network\\utils.py\", line 63, in response_chunks\n",
      "    for chunk in response.raw.stream(\n",
      "  File \"C:\\Users\\Palash\\anaconda3\\lib\\site-packages\\pip\\_vendor\\urllib3\\response.py\", line 573, in stream\n",
      "    data = self.read(amt=amt, decode_content=decode_content)\n",
      "  File \"C:\\Users\\Palash\\anaconda3\\lib\\site-packages\\pip\\_vendor\\urllib3\\response.py\", line 538, in read\n",
      "    raise IncompleteRead(self._fp_bytes_read, self.length_remaining)\n",
      "  File \"C:\\Users\\Palash\\anaconda3\\lib\\contextlib.py\", line 137, in __exit__\n",
      "    self.gen.throw(typ, value, traceback)\n",
      "  File \"C:\\Users\\Palash\\anaconda3\\lib\\site-packages\\pip\\_vendor\\urllib3\\response.py\", line 440, in _error_catcher\n",
      "    raise ReadTimeoutError(self._pool, None, \"Read timed out.\")\n",
      "pip._vendor.urllib3.exceptions.ReadTimeoutError: HTTPSConnectionPool(host='files.pythonhosted.org', port=443): Read timed out.\n"
     ]
    },
    {
     "name": "stdout",
     "output_type": "stream",
     "text": [
      "\n",
      "  Downloading pydataset-0.2.0.tar.gz (15.9 MB)\n",
      "     -----                                    2.1/15.9 MB 5.6 kB/s eta 0:41:05\n"
     ]
    }
   ],
   "source": [
    "pip install pydataset"
   ]
  },
  {
   "cell_type": "code",
   "execution_count": 3,
   "id": "9d211919",
   "metadata": {},
   "outputs": [
    {
     "ename": "ModuleNotFoundError",
     "evalue": "No module named 'pydataset'",
     "output_type": "error",
     "traceback": [
      "\u001b[1;31m---------------------------------------------------------------------------\u001b[0m",
      "\u001b[1;31mModuleNotFoundError\u001b[0m                       Traceback (most recent call last)",
      "\u001b[1;32m~\\AppData\\Local\\Temp\\ipykernel_8260\\582870094.py\u001b[0m in \u001b[0;36m<module>\u001b[1;34m\u001b[0m\n\u001b[1;32m----> 1\u001b[1;33m \u001b[1;32mfrom\u001b[0m \u001b[0mpydataset\u001b[0m \u001b[1;32mimport\u001b[0m \u001b[0mBikeshare\u001b[0m\u001b[1;33m\u001b[0m\u001b[1;33m\u001b[0m\u001b[0m\n\u001b[0m",
      "\u001b[1;31mModuleNotFoundError\u001b[0m: No module named 'pydataset'"
     ]
    }
   ],
   "source": [
    "from pydataset import Bikeshare"
   ]
  }
 ],
 "metadata": {
  "kernelspec": {
   "display_name": "Python 3 (ipykernel)",
   "language": "python",
   "name": "python3"
  },
  "language_info": {
   "codemirror_mode": {
    "name": "ipython",
    "version": 3
   },
   "file_extension": ".py",
   "mimetype": "text/x-python",
   "name": "python",
   "nbconvert_exporter": "python",
   "pygments_lexer": "ipython3",
   "version": "3.9.13"
  }
 },
 "nbformat": 4,
 "nbformat_minor": 5
}
